recipe_sha: 3610267290d8b8f268cecd167798b74c17a9562b2602eef4cb956f4101920488  # The hash of the recipe's meta.yaml at which this recipe failed to build.
skiplist: true # Set to true to skiplist this recipe so that it will be ignored as long as its latest commit is the one given above.
log: |-
  [34m      filename = __file__[0m
  [34m      with tokenize.open(__file__) as f:[0m
  [34m          setup_py_code = f.read()[0m
  [34m  else:[0m
  [34m      filename = "<auto-generated setuptools caller>"[0m
  [34m      setup_py_code = "from setuptools import setup; setup()"[0m
  [34m  [0m
  [34m  exec(compile(setup_py_code, filename, "exec"))[0m
  [34m  '"'"''"'"''"'"' % ('"'"'/opt/conda/conda-bld/gimmemotifs_1718121272991/work/setup.py'"'"',), "<pip-setuptools-caller>", "exec"))' egg_info --egg-base /tmp/pip-pip-egg-info-n2ula4ta[0m
    [1;35mcwd[0m: /opt/conda/conda-bld/gimmemotifs_1718121272991/work/
    Preparing metadata (setup.py) ... [?25l[?25herror
  [1;31merror[0m: [1mmetadata-generation-failed[0m

  [31m[0m Encountered error while generating package metadata.
  [31m>[0m See above for output.

  [1;35mnote[0m: This is an issue with the package mentioned above, not pip.
  [1;36mhint[0m: See above for details.
  Exception information:
  Traceback (most recent call last):
    File "/opt/conda/conda-bld/gimmemotifs_1718121272991/_h_env_placehold_placehold_placehold_placehold_placehold_placehold_placehold_placehold_placehold_placehold_placehold_placehold_placehold_placehold_placehold_placehold_placehold_placehold_placehold_placehold_p/lib/python3.12/site-packages/pip/_internal/operations/build/metadata_legacy.py", line 64, in generate_metadata
      call_subprocess(
    File "/opt/conda/conda-bld/gimmemotifs_1718121272991/_h_env_placehold_placehold_placehold_placehold_placehold_placehold_placehold_placehold_placehold_placehold_placehold_placehold_placehold_placehold_placehold_placehold_placehold_placehold_placehold_placehold_p/lib/python3.12/site-packages/pip/_internal/utils/subprocess.py", line 224, in call_subprocess
      raise error
  pip._internal.exceptions.InstallationSubprocessError: python setup.py egg_info exited with 1

  The above exception was the direct cause of the following exception:

  Traceback (most recent call last):
    File "/opt/conda/conda-bld/gimmemotifs_1718121272991/_h_env_placehold_placehold_placehold_placehold_placehold_placehold_placehold_placehold_placehold_placehold_placehold_placehold_placehold_placehold_placehold_placehold_placehold_placehold_placehold_placehold_p/lib/python3.12/site-packages/pip/_internal/cli/base_command.py", line 180, in exc_logging_wrapper
      status = run_func(*args)
               ^^^^^^^^^^^^^^^
    File "/opt/conda/conda-bld/gimmemotifs_1718121272991/_h_env_placehold_placehold_placehold_placehold_placehold_placehold_placehold_placehold_placehold_placehold_placehold_placehold_placehold_placehold_placehold_placehold_placehold_placehold_placehold_placehold_p/lib/python3.12/site-packages/pip/_internal/cli/req_command.py", line 245, in wrapper
      return func(self, options, args)
             ^^^^^^^^^^^^^^^^^^^^^^^^^
    File "/opt/conda/conda-bld/gimmemotifs_1718121272991/_h_env_placehold_placehold_placehold_placehold_placehold_placehold_placehold_placehold_placehold_placehold_placehold_placehold_placehold_placehold_placehold_placehold_placehold_placehold_placehold_placehold_p/lib/python3.12/site-packages/pip/_internal/commands/install.py", line 377, in run
      requirement_set = resolver.resolve(
                        ^^^^^^^^^^^^^^^^^
    File "/opt/conda/conda-bld/gimmemotifs_1718121272991/_h_env_placehold_placehold_placehold_placehold_placehold_placehold_placehold_placehold_placehold_placehold_placehold_placehold_placehold_placehold_placehold_placehold_placehold_placehold_placehold_placehold_p/lib/python3.12/site-packages/pip/_internal/resolution/resolvelib/resolver.py", line 76, in resolve
      collected = self.factory.collect_root_requirements(root_reqs)
                  ^^^^^^^^^^^^^^^^^^^^^^^^^^^^^^^^^^^^^^^^^^^^^^^^^
    File "/opt/conda/conda-bld/gimmemotifs_1718121272991/_h_env_placehold_placehold_placehold_placehold_placehold_placehold_placehold_placehold_placehold_placehold_placehold_placehold_placehold_placehold_placehold_placehold_placehold_placehold_placehold_placehold_p/lib/python3.12/site-packages/pip/_internal/resolution/resolvelib/factory.py", line 534, in collect_root_requirements
      reqs = list(
             ^^^^^
    File "/opt/conda/conda-bld/gimmemotifs_1718121272991/_h_env_placehold_placehold_placehold_placehold_placehold_placehold_placehold_placehold_placehold_placehold_placehold_placehold_placehold_placehold_placehold_placehold_placehold_placehold_placehold_placehold_p/lib/python3.12/site-packages/pip/_internal/resolution/resolvelib/factory.py", line 490, in _make_requirements_from_install_req
      cand = self._make_base_candidate_from_link(
             ^^^^^^^^^^^^^^^^^^^^^^^^^^^^^^^^^^^^
    File "/opt/conda/conda-bld/gimmemotifs_1718121272991/_h_env_placehold_placehold_placehold_placehold_placehold_placehold_placehold_placehold_placehold_placehold_placehold_placehold_placehold_placehold_placehold_placehold_placehold_placehold_placehold_placehold_p/lib/python3.12/site-packages/pip/_internal/resolution/resolvelib/factory.py", line 228, in _make_base_candidate_from_link
      self._link_candidate_cache[link] = LinkCandidate(
                                         ^^^^^^^^^^^^^^
    File "/opt/conda/conda-bld/gimmemotifs_1718121272991/_h_env_placehold_placehold_placehold_placehold_placehold_placehold_placehold_placehold_placehold_placehold_placehold_placehold_placehold_placehold_placehold_placehold_placehold_placehold_placehold_placehold_p/lib/python3.12/site-packages/pip/_internal/resolution/resolvelib/candidates.py", line 290, in __init__
      super().__init__(
    File "/opt/conda/conda-bld/gimmemotifs_1718121272991/_h_env_placehold_placehold_placehold_placehold_placehold_placehold_placehold_placehold_placehold_placehold_placehold_placehold_placehold_placehold_placehold_placehold_placehold_placehold_placehold_placehold_p/lib/python3.12/site-packages/pip/_internal/resolution/resolvelib/candidates.py", line 156, in __init__
      self.dist = self._prepare()
                  ^^^^^^^^^^^^^^^
    File "/opt/conda/conda-bld/gimmemotifs_1718121272991/_h_env_placehold_placehold_placehold_placehold_placehold_placehold_placehold_placehold_placehold_placehold_placehold_placehold_placehold_placehold_placehold_placehold_placehold_placehold_placehold_placehold_p/lib/python3.12/site-packages/pip/_internal/resolution/resolvelib/candidates.py", line 222, in _prepare
      dist = self._prepare_distribution()
             ^^^^^^^^^^^^^^^^^^^^^^^^^^^^
    File "/opt/conda/conda-bld/gimmemotifs_1718121272991/_h_env_placehold_placehold_placehold_placehold_placehold_placehold_placehold_placehold_placehold_placehold_placehold_placehold_placehold_placehold_placehold_placehold_placehold_placehold_placehold_placehold_p/lib/python3.12/site-packages/pip/_internal/resolution/resolvelib/candidates.py", line 301, in _prepare_distribution
      return preparer.prepare_linked_requirement(self._ireq, parallel_builds=True)
             ^^^^^^^^^^^^^^^^^^^^^^^^^^^^^^^^^^^^^^^^^^^^^^^^^^^^^^^^^^^^^^^^^^^^^
    File "/opt/conda/conda-bld/gimmemotifs_1718121272991/_h_env_placehold_placehold_placehold_placehold_placehold_placehold_placehold_placehold_placehold_placehold_placehold_placehold_placehold_placehold_placehold_placehold_placehold_placehold_placehold_placehold_p/lib/python3.12/site-packages/pip/_internal/operations/prepare.py", line 525, in prepare_linked_requirement
      return self._prepare_linked_requirement(req, parallel_builds)
             ^^^^^^^^^^^^^^^^^^^^^^^^^^^^^^^^^^^^^^^^^^^^^^^^^^^^^^
    File "/opt/conda/conda-bld/gimmemotifs_1718121272991/_h_env_placehold_placehold_placehold_placehold_placehold_placehold_placehold_placehold_placehold_placehold_placehold_placehold_placehold_placehold_placehold_placehold_placehold_placehold_placehold_placehold_p/lib/python3.12/site-packages/pip/_internal/operations/prepare.py", line 640, in _prepare_linked_requirement
      dist = _get_prepared_distribution(
             ^^^^^^^^^^^^^^^^^^^^^^^^^^^
    File "/opt/conda/conda-bld/gimmemotifs_1718121272991/_h_env_placehold_placehold_placehold_placehold_placehold_placehold_placehold_placehold_placehold_placehold_placehold_placehold_placehold_placehold_placehold_placehold_placehold_placehold_placehold_placehold_p/lib/python3.12/site-packages/pip/_internal/operations/prepare.py", line 71, in _get_prepared_distribution
      abstract_dist.prepare_distribution_metadata(
    File "/opt/conda/conda-bld/gimmemotifs_1718121272991/_h_env_placehold_placehold_placehold_placehold_placehold_placehold_placehold_placehold_placehold_placehold_placehold_placehold_placehold_placehold_placehold_placehold_placehold_placehold_placehold_placehold_p/lib/python3.12/site-packages/pip/_internal/distributions/sdist.py", line 67, in prepare_distribution_metadata
      self.req.prepare_metadata()
    File "/opt/conda/conda-bld/gimmemotifs_1718121272991/_h_env_placehold_placehold_placehold_placehold_placehold_placehold_placehold_placehold_placehold_placehold_placehold_placehold_placehold_placehold_placehold_placehold_placehold_placehold_placehold_placehold_p/lib/python3.12/site-packages/pip/_internal/req/req_install.py", line 585, in prepare_metadata
      self.metadata_directory = generate_metadata_legacy(
                                ^^^^^^^^^^^^^^^^^^^^^^^^^
    File "/opt/conda/conda-bld/gimmemotifs_1718121272991/_h_env_placehold_placehold_placehold_placehold_placehold_placehold_placehold_placehold_placehold_placehold_placehold_placehold_placehold_placehold_placehold_placehold_placehold_placehold_placehold_placehold_p/lib/python3.12/site-packages/pip/_internal/operations/build/metadata_legacy.py", line 71, in generate_metadata
      raise MetadataGenerationFailed(package_details=details) from error
  pip._internal.exceptions.MetadataGenerationFailed: metadata generation failed
  Remote version of pip: 24.0
  Local version of pip:  24.0
  Was pip installed by pip? False
  Removed file:///opt/conda/conda-bld/gimmemotifs_1718121272991/work from build tracker '/tmp/pip-build-tracker-8pbev87f'
  Removed build tracker: '/tmp/pip-build-tracker-8pbev87f'
  Traceback (most recent call last):
    File "/opt/conda/bin/conda-build", line 11, in <module>
      sys.exit(execute())
    File "/opt/conda/lib/python3.10/site-packages/conda_build/cli/main_build.py", line 590, in execute
      api.build(
    File "/opt/conda/lib/python3.10/site-packages/conda_build/api.py", line 250, in build
      return build_tree(
    File "/opt/conda/lib/python3.10/site-packages/conda_build/build.py", line 3638, in build_tree
      packages_from_this = build(
    File "/opt/conda/lib/python3.10/site-packages/conda_build/build.py", line 2711, in build
      newly_built_packages = bundlers[pkg_type](output_d, m, env, stats)
    File "/opt/conda/lib/python3.10/site-packages/conda_build/build.py", line 1784, in bundle_conda
      utils.check_call_env(
    File "/opt/conda/lib/python3.10/site-packages/conda_build/utils.py", line 405, in check_call_env
      return _func_defaulting_env_to_os_environ("call", *popenargs, **kwargs)
    File "/opt/conda/lib/python3.10/site-packages/conda_build/utils.py", line 381, in _func_defaulting_env_to_os_environ
      raise subprocess.CalledProcessError(proc.returncode, _args)
  subprocess.CalledProcessError: Command '['/usr/bin/bash', '-e', '/opt/conda/conda-bld/gimmemotifs_1718121272991/work/output_script.sh']' returned non-zero exit status 1.
# Last 100 lines of the build log.
