recipe_sha: 400ed2c0710342dc29523fa08cc66e0bbb7567fabf768184c9bb8ce3c8141cf4  # The hash of the recipe's meta.yaml at which this recipe failed to build.
skiplist: true # Set to true to skiplist this recipe so that it will be ignored as long as its latest commit is the one given above.
log: |-
  _CONDA_PYTHON_SYSCONFIGDATA_NAME=_sysconfigdata_x86_64_apple_darwin13_4_0
  ac_cv_func_malloc_0_nonnull=yes
  ac_cv_func_realloc_0_nonnull=yes
  build_alias=x86_64-apple-darwin13.4.0
  host_alias=x86_64-apple-darwin13.4.0
  INFO: activate_clangxx_osx-64.sh made the following environmental changes:
  CLANGXX=x86_64-apple-darwin13.4.0-clang
  CXX=x86_64-apple-darwin13.4.0-clang
  CXXFLAGS=-march=core2 -mtune=haswell -mssse3 -ftree-vectorize -fPIC -fstack-protector-strong -O2 -pipe -stdlib=libc -fvisibility-inlines-hidden -fmessage-length=0 -isystem $PREFIX/include -fdebug-prefix-map=$SRC_DIR=/usr/local/src/conda/iced-0.5.10 -fdebug-prefix-map=$PREFIX=/usr/local/src/conda-prefix
  CXX_FOR_BUILD=$BUILD_PREFIX/bin/x86_64-apple-darwin13.4.0-clang
  DEBUG_CXXFLAGS=-march=core2 -mtune=haswell -mssse3 -ftree-vectorize -fPIC -fstack-protector-strong -O2 -pipe -stdlib=libc -fvisibility-inlines-hidden -fmessage-length=0 -Og -g -Wall -Wextra -isystem $PREFIX/include -fdebug-prefix-map=$SRC_DIR=/usr/local/src/conda/iced-0.5.10 -fdebug-prefix-map=$PREFIX=/usr/local/src/conda-prefix
  iced
  Processing iced/_filter_.pyx
  Processing iced/normalization/_normalization_.pyx
  Using pip 24.0 from $PREFIX/lib/python3.12/site-packages/pip (python 3.12)
  Non-user install because user site-packages disabled
  Ignoring indexes: https://pypi.org/simple
  Created temporary directory: /private/tmp/pip-build-tracker-zu5vyi_p
  Initialized build tracking at /private/tmp/pip-build-tracker-zu5vyi_p
  Created build tracker: /private/tmp/pip-build-tracker-zu5vyi_p
  Entered build tracker: /private/tmp/pip-build-tracker-zu5vyi_p
  Created temporary directory: /private/tmp/pip-install-usxqfwkz
  Created temporary directory: /private/tmp/pip-ephem-wheel-cache-6k98c0ng
  Processing $SRC_DIR
    Added file://$SRC_DIR to build tracker '/private/tmp/pip-build-tracker-zu5vyi_p'
    Created temporary directory: /private/tmp/pip-modern-metadata-8ggb3l2k
    Preparing metadata (pyproject.toml): started
    Preparing metadata (pyproject.toml): finished with status 'error'
  Exception information:
  Traceback (most recent call last):
    File "$PREFIX/lib/python3.12/site-packages/pip/_internal/operations/build/metadata.py", line 35, in generate_metadata
      distinfo_dir = backend.prepare_metadata_for_build_wheel(metadata_dir)
                     ^^^^^^^^^^^^^^^^^^^^^^^^^^^^^^^^^^^^^^^^^^^^^^^^^^^^^^
    File "$PREFIX/lib/python3.12/site-packages/pip/_internal/utils/misc.py", line 766, in prepare_metadata_for_build_wheel
      return super().prepare_metadata_for_build_wheel(
             ^^^^^^^^^^^^^^^^^^^^^^^^^^^^^^^^^^^^^^^^^
    File "$PREFIX/lib/python3.12/site-packages/pip/_vendor/pyproject_hooks/_impl.py", line 186, in prepare_metadata_for_build_wheel
      return self._call_hook('prepare_metadata_for_build_wheel', {
             ^^^^^^^^^^^^^^^^^^^^^^^^^^^^^^^^^^^^^^^^^^^^^^^^^^^^^
    File "$PREFIX/lib/python3.12/site-packages/pip/_vendor/pyproject_hooks/_impl.py", line 311, in _call_hook
      self._subprocess_runner(
    File "$PREFIX/lib/python3.12/site-packages/pip/_internal/utils/subprocess.py", line 252, in runner
      call_subprocess(
    File "$PREFIX/lib/python3.12/site-packages/pip/_internal/utils/subprocess.py", line 224, in call_subprocess
      raise error
  pip._internal.exceptions.InstallationSubprocessError: Preparing metadata (pyproject.toml) exited with 1

  The above exception was the direct cause of the following exception:

  Traceback (most recent call last):
    File "$PREFIX/lib/python3.12/site-packages/pip/_internal/cli/base_command.py", line 180, in exc_logging_wrapper
      status = run_func(*args)
               ^^^^^^^^^^^^^^^
    File "$PREFIX/lib/python3.12/site-packages/pip/_internal/cli/req_command.py", line 245, in wrapper
      return func(self, options, args)
             ^^^^^^^^^^^^^^^^^^^^^^^^^
    File "$PREFIX/lib/python3.12/site-packages/pip/_internal/commands/install.py", line 377, in run
      requirement_set = resolver.resolve(
                        ^^^^^^^^^^^^^^^^^
    File "$PREFIX/lib/python3.12/site-packages/pip/_internal/resolution/resolvelib/resolver.py", line 76, in resolve
      collected = self.factory.collect_root_requirements(root_reqs)
                  ^^^^^^^^^^^^^^^^^^^^^^^^^^^^^^^^^^^^^^^^^^^^^^^^^
    File "$PREFIX/lib/python3.12/site-packages/pip/_internal/resolution/resolvelib/factory.py", line 534, in collect_root_requirements
      reqs = list(
             ^^^^^
    File "$PREFIX/lib/python3.12/site-packages/pip/_internal/resolution/resolvelib/factory.py", line 490, in _make_requirements_from_install_req
      cand = self._make_base_candidate_from_link(
             ^^^^^^^^^^^^^^^^^^^^^^^^^^^^^^^^^^^^
    File "$PREFIX/lib/python3.12/site-packages/pip/_internal/resolution/resolvelib/factory.py", line 228, in _make_base_candidate_from_link
      self._link_candidate_cache[link] = LinkCandidate(
                                         ^^^^^^^^^^^^^^
    File "$PREFIX/lib/python3.12/site-packages/pip/_internal/resolution/resolvelib/candidates.py", line 290, in __init__
      super().__init__(
    File "$PREFIX/lib/python3.12/site-packages/pip/_internal/resolution/resolvelib/candidates.py", line 156, in __init__
      self.dist = self._prepare()
                  ^^^^^^^^^^^^^^^
    File "$PREFIX/lib/python3.12/site-packages/pip/_internal/resolution/resolvelib/candidates.py", line 222, in _prepare
      dist = self._prepare_distribution()
             ^^^^^^^^^^^^^^^^^^^^^^^^^^^^
    File "$PREFIX/lib/python3.12/site-packages/pip/_internal/resolution/resolvelib/candidates.py", line 301, in _prepare_distribution
      return preparer.prepare_linked_requirement(self._ireq, parallel_builds=True)
             ^^^^^^^^^^^^^^^^^^^^^^^^^^^^^^^^^^^^^^^^^^^^^^^^^^^^^^^^^^^^^^^^^^^^^
    File "$PREFIX/lib/python3.12/site-packages/pip/_internal/operations/prepare.py", line 525, in prepare_linked_requirement
      return self._prepare_linked_requirement(req, parallel_builds)
             ^^^^^^^^^^^^^^^^^^^^^^^^^^^^^^^^^^^^^^^^^^^^^^^^^^^^^^
    File "$PREFIX/lib/python3.12/site-packages/pip/_internal/operations/prepare.py", line 640, in _prepare_linked_requirement
      dist = _get_prepared_distribution(
             ^^^^^^^^^^^^^^^^^^^^^^^^^^^
    File "$PREFIX/lib/python3.12/site-packages/pip/_internal/operations/prepare.py", line 71, in _get_prepared_distribution
      abstract_dist.prepare_distribution_metadata(
    File "$PREFIX/lib/python3.12/site-packages/pip/_internal/distributions/sdist.py", line 67, in prepare_distribution_metadata
      self.req.prepare_metadata()
    File "$PREFIX/lib/python3.12/site-packages/pip/_internal/req/req_install.py", line 579, in prepare_metadata
      self.metadata_directory = generate_metadata(
                                ^^^^^^^^^^^^^^^^^^
    File "$PREFIX/lib/python3.12/site-packages/pip/_internal/operations/build/metadata.py", line 37, in generate_metadata
      raise MetadataGenerationFailed(package_details=details) from error
  pip._internal.exceptions.MetadataGenerationFailed: metadata generation failed
  Removed file://$SRC_DIR from build tracker '/private/tmp/pip-build-tracker-zu5vyi_p'
  Removed build tracker: '/private/tmp/pip-build-tracker-zu5vyi_p'
# Last 100 lines of the build log.
