recipe_sha: b934e4743b3df2f177bba61bcc0775def99e617355b10f5064a9bf1b16a92eb5  # The hash of the recipe's meta.yaml at which this recipe failed to build.
skiplist: false # Set to true to skiplist this recipe so that it will be ignored as long as its latest commit is the one given above.
log: |2-
      File "<string>", line 3, in <module>
    ModuleNotFoundError: No module named 'setuptools_scm'
    [1;31merror[0m: [1msubprocess-exited-with-error[0m

    [31m[0m [32mPreparing metadata [0m[1;32m([0m[32mpyproject.toml[0m[1;32m)[0m did not run successfully.
    [31m[0m exit code: [1;36m1[0m
    [31m>[0m See above for output.

    [1;35mnote[0m: This error originates from a subprocess, and is likely not a problem with pip.
    [1;35mfull command[0m: [34m/opt/conda/conda-bld/fast-edit-distance_1734138198276/_h_env_placehold_placehold_placehold_placehold_placehold_placehold_placehold_placehold_placehold_placehold_placehold_placehold_placehold_placehold_placehold_placehold_placehold_placehold_placehold_plac/bin/python /opt/conda/conda-bld/fast-edit-distance_1734138198276/_h_env_placehold_placehold_placehold_placehold_placehold_placehold_placehold_placehold_placehold_placehold_placehold_placehold_placehold_placehold_placehold_placehold_placehold_placehold_placehold_plac/lib/python3.10/site-packages/pip/_vendor/pyproject_hooks/_in_process/_in_process.py prepare_metadata_for_build_wheel /tmp/tmp71zizwsh[0m
    [1;35mcwd[0m: /opt/conda/conda-bld/fast-edit-distance_1734138198276/work
    Preparing metadata (pyproject.toml): finished with status 'error'
  [1;31merror[0m: [1mmetadata-generation-failed[0m

  [31m[0m Encountered error while generating package metadata.
  [31m>[0m See above for output.

  [1;35mnote[0m: This is an issue with the package mentioned above, not pip.
  [1;36mhint[0m: See above for details.
  Exception information:
  Traceback (most recent call last):
    File "$PREFIX/lib/python3.10/site-packages/pip/_internal/operations/build/metadata.py", line 35, in generate_metadata
      distinfo_dir = backend.prepare_metadata_for_build_wheel(metadata_dir)
    File "$PREFIX/lib/python3.10/site-packages/pip/_internal/utils/misc.py", line 722, in prepare_metadata_for_build_wheel
      return super().prepare_metadata_for_build_wheel(
    File "$PREFIX/lib/python3.10/site-packages/pip/_vendor/pyproject_hooks/_impl.py", line 186, in prepare_metadata_for_build_wheel
      return self._call_hook('prepare_metadata_for_build_wheel', {
    File "$PREFIX/lib/python3.10/site-packages/pip/_vendor/pyproject_hooks/_impl.py", line 311, in _call_hook
      self._subprocess_runner(
    File "$PREFIX/lib/python3.10/site-packages/pip/_internal/utils/subprocess.py", line 237, in runner
      call_subprocess(
    File "$PREFIX/lib/python3.10/site-packages/pip/_internal/utils/subprocess.py", line 209, in call_subprocess
      raise error
  pip._internal.exceptions.InstallationSubprocessError: Preparing metadata (pyproject.toml) exited with 1

  The above exception was the direct cause of the following exception:

  Traceback (most recent call last):
    File "$PREFIX/lib/python3.10/site-packages/pip/_internal/cli/base_command.py", line 105, in _run_wrapper
      status = _inner_run()
    File "$PREFIX/lib/python3.10/site-packages/pip/_internal/cli/base_command.py", line 96, in _inner_run
      return self.run(options, args)
    File "$PREFIX/lib/python3.10/site-packages/pip/_internal/cli/req_command.py", line 67, in wrapper
      return func(self, options, args)
    File "$PREFIX/lib/python3.10/site-packages/pip/_internal/commands/install.py", line 379, in run
      requirement_set = resolver.resolve(
    File "$PREFIX/lib/python3.10/site-packages/pip/_internal/resolution/resolvelib/resolver.py", line 76, in resolve
      collected = self.factory.collect_root_requirements(root_reqs)
    File "$PREFIX/lib/python3.10/site-packages/pip/_internal/resolution/resolvelib/factory.py", line 545, in collect_root_requirements
      reqs = list(
    File "$PREFIX/lib/python3.10/site-packages/pip/_internal/resolution/resolvelib/factory.py", line 501, in _make_requirements_from_install_req
      cand = self._make_base_candidate_from_link(
    File "$PREFIX/lib/python3.10/site-packages/pip/_internal/resolution/resolvelib/factory.py", line 233, in _make_base_candidate_from_link
      self._link_candidate_cache[link] = LinkCandidate(
    File "$PREFIX/lib/python3.10/site-packages/pip/_internal/resolution/resolvelib/candidates.py", line 304, in __init__
      super().__init__(
    File "$PREFIX/lib/python3.10/site-packages/pip/_internal/resolution/resolvelib/candidates.py", line 159, in __init__
      self.dist = self._prepare()
    File "$PREFIX/lib/python3.10/site-packages/pip/_internal/resolution/resolvelib/candidates.py", line 236, in _prepare
      dist = self._prepare_distribution()
    File "$PREFIX/lib/python3.10/site-packages/pip/_internal/resolution/resolvelib/candidates.py", line 315, in _prepare_distribution
      return preparer.prepare_linked_requirement(self._ireq, parallel_builds=True)
    File "$PREFIX/lib/python3.10/site-packages/pip/_internal/operations/prepare.py", line 527, in prepare_linked_requirement
      return self._prepare_linked_requirement(req, parallel_builds)
    File "$PREFIX/lib/python3.10/site-packages/pip/_internal/operations/prepare.py", line 642, in _prepare_linked_requirement
      dist = _get_prepared_distribution(
    File "$PREFIX/lib/python3.10/site-packages/pip/_internal/operations/prepare.py", line 72, in _get_prepared_distribution
      abstract_dist.prepare_distribution_metadata(
    File "$PREFIX/lib/python3.10/site-packages/pip/_internal/distributions/sdist.py", line 69, in prepare_distribution_metadata
      self.req.prepare_metadata()
    File "$PREFIX/lib/python3.10/site-packages/pip/_internal/req/req_install.py", line 575, in prepare_metadata
      self.metadata_directory = generate_metadata(
    File "$PREFIX/lib/python3.10/site-packages/pip/_internal/operations/build/metadata.py", line 37, in generate_metadata
      raise MetadataGenerationFailed(package_details=details) from error
  pip._internal.exceptions.MetadataGenerationFailed: metadata generation failed
  Removed file://$SRC_DIR from build tracker '/tmp/pip-build-tracker-k1czbrag'
  Removed build tracker: '/tmp/pip-build-tracker-k1czbrag'
  Traceback (most recent call last):
    File "/opt/conda/lib/python3.10/site-packages/conda_build/build.py", line 2558, in build
      utils.check_call_env(
    File "/opt/conda/lib/python3.10/site-packages/conda_build/utils.py", line 404, in check_call_env
      return _func_defaulting_env_to_os_environ("call", *popenargs, **kwargs)
    File "/opt/conda/lib/python3.10/site-packages/conda_build/utils.py", line 380, in _func_defaulting_env_to_os_environ
      raise subprocess.CalledProcessError(proc.returncode, _args)
  subprocess.CalledProcessError: Command '['/bin/bash', '-o', 'errexit', '/opt/conda/conda-bld/fast-edit-distance_1734138198276/work/conda_build.sh']' returned non-zero exit status 1.

  The above exception was the direct cause of the following exception:

  Traceback (most recent call last):
    File "/opt/conda/bin/conda-build", line 11, in <module>
      sys.exit(execute())
    File "/opt/conda/lib/python3.10/site-packages/conda_build/cli/main_build.py", line 589, in execute
      api.build(
    File "/opt/conda/lib/python3.10/site-packages/conda_build/api.py", line 209, in build
      return build_tree(
    File "/opt/conda/lib/python3.10/site-packages/conda_build/build.py", line 3712, in build_tree
      packages_from_this = build(
    File "/opt/conda/lib/python3.10/site-packages/conda_build/build.py", line 2566, in build
      raise BuildScriptException(str(exc), caused_by=exc) from exc
  conda_build.exceptions.BuildScriptException: Command '['/bin/bash', '-o', 'errexit', '/opt/conda/conda-bld/fast-edit-distance_1734138198276/work/conda_build.sh']' returned non-zero exit status 1.
# Last 100 lines of the build log.
