recipe_sha: 0a9d1b56a7039afc1ef5c0c1127f4dcae47e55ff4ae9f8259fcfbbc9d4748893  # The hash of the recipe's meta.yaml at which this recipe failed to build.
skiplist: false # Set to true to skiplist this recipe so that it will be ignored as long as its latest commit is the one given above.
log: |2-
      libzlib:          1.3.1-hb9d3cd8_2          conda-forge
      ncurses:          6.5-he02047a_1            conda-forge
      openssl:          3.4.0-hb9d3cd8_0          conda-forge
      pip:              24.3.1-pyh8b19718_0       conda-forge
      python:           3.9.21-h9c0c6dc_1_cpython conda-forge
      readline:         8.2-h8228510_1            conda-forge
      semantic_version: 2.10.0-pyhd8ed1ab_0       conda-forge
      setuptools:       75.6.0-pyhff2d567_1       conda-forge
      setuptools-rust:  1.10.2-pyhd8ed1ab_1       conda-forge
      tk:               8.6.13-noxft_h4845f30_101 conda-forge
      tzdata:           2024b-hc8b5060_0          conda-forge
      wheel:            0.45.1-pyhd8ed1ab_1       conda-forge

  Preparing transaction: ...working... done
  Verifying transaction: ...working... done
  Executing transaction: ...working... done
  Reloading output folder (local, file:///opt/host-conda-bld): ...working... done
  Solving environment (_test_env): ...working... done

  ## Package Plan ##

    environment location: /opt/conda/conda-bld/gb-io_1734130397804/_build_env


  The following NEW packages will be INSTALLED:

      _libgcc_mutex:                     0.1-conda_forge     conda-forge
      _openmp_mutex:                     4.5-2_gnu           conda-forge
      binutils_impl_linux-64:            2.43-h4bf12b8_2     conda-forge
      binutils_linux-64:                 2.43-h4852527_2     conda-forge
      gcc_impl_linux-64:                 13.3.0-hfea6d02_1   conda-forge
      gcc_linux-64:                      13.3.0-hc28eda2_7   conda-forge
      gxx_impl_linux-64:                 13.3.0-hdbfa832_1   conda-forge
      gxx_linux-64:                      13.3.0-h6834431_7   conda-forge
      kernel-headers_linux-64:           3.10.0-he073ed8_18  conda-forge
      ld_impl_linux-64:                  2.43-h712a8e2_2     conda-forge
      libgcc:                            14.2.0-h77fa898_1   conda-forge
      libgcc-devel_linux-64:             13.3.0-h84ea5a7_101 conda-forge
      libgomp:                           14.2.0-h77fa898_1   conda-forge
      libsanitizer:                      13.3.0-heb74ff8_1   conda-forge
      libstdcxx:                         14.2.0-hc0a3c3a_1   conda-forge
      libstdcxx-devel_linux-64:          13.3.0-h84ea5a7_101 conda-forge
      libzlib:                           1.3.1-hb9d3cd8_2    conda-forge
      rust:                              1.83.0-h1a8d7c4_0   conda-forge
      rust-std-x86_64-unknown-linux-gnu: 1.83.0-h2c6d0dc_0   conda-forge
      rust_linux-64:                     1.83.0-h9a957ce_1   conda-forge
      sysroot_linux-64:                  2.17-h4a8ded7_18    conda-forge
      tzdata:                            2024b-hc8b5060_0    conda-forge

  Preparing transaction: ...working... done
  Verifying transaction: ...working... done
  Executing transaction: ...working... done
  Extracting download
  WARNING:libarchive:Write failed
  WARNING:libarchive:Write failed
  Traceback (most recent call last):
    File "/opt/conda/lib/python3.10/site-packages/conda_build/utils.py", line 857, in tar_xf
      libarchive.extract_file(tarball, flags)
    File "/opt/conda/lib/python3.10/site-packages/libarchive/extract.py", line 82, in extract_file
      extract_entries(archive, flags)
    File "/opt/conda/lib/python3.10/site-packages/libarchive/extract.py", line 62, in extract_entries
      write_header(write_p, entry._entry_p)
    File "/opt/conda/lib/python3.10/site-packages/libarchive/ffi.py", line 98, in check_int
      raise archive_error(args[0], retcode)
  libarchive.exception.ArchiveError: Can't create 'gb_io-0.3.3/crates/libc/src/unix/linux_like/linux/musl/b32/mips' (errno=28, retcode=-25, archive_p=94727376542160)

  During handling of the above exception, another exception occurred:

  Traceback (most recent call last):
    File "/opt/conda/bin/conda-build", line 11, in <module>
      sys.exit(execute())
    File "/opt/conda/lib/python3.10/site-packages/conda_build/cli/main_build.py", line 589, in execute
      api.build(
    File "/opt/conda/lib/python3.10/site-packages/conda_build/api.py", line 209, in build
      return build_tree(
    File "/opt/conda/lib/python3.10/site-packages/conda_build/build.py", line 3712, in build_tree
      packages_from_this = build(
    File "/opt/conda/lib/python3.10/site-packages/conda_build/build.py", line 2449, in build
      try_download(m, no_download_source=False, raise_error=True)
    File "/opt/conda/lib/python3.10/site-packages/conda_build/render.py", line 762, in try_download
      source.provide(metadata)
    File "/opt/conda/lib/python3.10/site-packages/conda_build/source.py", line 1035, in provide
      unpack(
    File "/opt/conda/lib/python3.10/site-packages/conda_build/source.py", line 180, in unpack
      tar_xf(src_path, tmpdir)
    File "/opt/conda/lib/python3.10/site-packages/conda_build/utils.py", line 865, in tar_xf
      _tar_xf_fallback(tarball, dir_path)
    File "/opt/conda/lib/python3.10/site-packages/conda_build/utils.py", line 810, in _tar_xf_fallback
      t.extractall(path=dir_path)
    File "/opt/conda/lib/python3.10/tarfile.py", line 2293, in extractall
      self._extract_one(tarinfo, path, set_attrs=not tarinfo.isdir(),
    File "/opt/conda/lib/python3.10/tarfile.py", line 2360, in _extract_one
      self._handle_fatal_error(e)
    File "/opt/conda/lib/python3.10/tarfile.py", line 2356, in _extract_one
      self._extract_member(tarinfo, os.path.join(path, tarinfo.name),
    File "/opt/conda/lib/python3.10/tarfile.py", line 2439, in _extract_member
      self.makefile(tarinfo, targetpath)
    File "/opt/conda/lib/python3.10/tarfile.py", line 2484, in makefile
      with bltn_open(targetpath, "wb") as target:
  OSError: [Errno 28] No space left on device
# Last 100 lines of the build log.
